const catchAsyncError = (fn) => (req, res, next) => {
  fn(req, res, next).catch(next);
};

export default catchAsyncError;
